Workbook

Sheet Solutions
A1: param Bud := 250; | C1: param Bud := 250; | E1: param Bud := 300; | G1: param Bud := 300; | I1: param Bud := 350; | K1: param Bud := 350;
A3: param alp := 0.85; | C3: param alp := 0.98; | E3: param alp := 0.96; | G3: param alp := 0.98; | I3: param alp := 0.98; | K3: param alp := 0.87;
A4: param bet := 0.94; | C4: param bet := 0.85; | E4: param bet := 0.85; | G4: param bet := 0.71; | I4: param bet := 0.6; | K4: param bet := 0.73;
A6: Cost_Sec = 133 | C6: Cost_Sec = 71.7 | E6: Cost_Sec = 125.2 | G6: Cost_Sec = 71.7 | I6: Cost_Sec = 71.7 | K6: Cost_Sec = 130.4
A8: Cost_Ele = 116.9 | C8: Cost_Ele = 178.1 | E8: Cost_Ele = 174.7 | G8: Cost_Ele = 228.1 | I8: Cost_Ele = 278.3 | K8: Cost_Ele = 219.6
A10: Create_Sec = 2400 | C10: Create_Sec = 1400 | E10: Create_Sec = 2100 | G10: Create_Sec = 1400 | I10: Create_Sec = 1400 | K10: Create_Sec = 2300
A12: Create_Ele = 2900 | C12: Create_Ele = 4150 | E12: Create_Ele = 3950 | G12: Create_Ele = 5400 | I12: Create_Ele = 6700 | K12: Create_Ele = 5200
A14: Overcrowd_Sec = 0.405708 | C14: Overcrowd_Sec = 0.457379 | E14: Overcrowd_Sec = 0.420821 | G14: Overcrowd_Sec = 0.457379 | I14: Overcrowd_Sec = 0.457379 | K14: Overcrowd_Sec = 0.41071
A16: Overcrowd_Ele = 0.502557 | C16: Overcrowd_Ele = 0.455099 | E16: Overcrowd_Ele = 0.46249 | G16: Overcrowd_Ele = 0.410547 | I16: Overcrowd_Ele = 0.367018 | K16: Overcrowd_Ele = 0.417491
A18: Gurobi 7.0.0: optimal solution; objective 5225.6 | C18: Gurobi 7.0.0: optimal solution; objective 5495.6 | E18: Gurobi 7.0.0: optimal solution; objective 5952.7 | G18: Gurobi 7.0.0: optimal solution; objective 6748.8 | I18: Gurobi 7.0.0: optimal solution; objective 8012.2 | K18: Gurobi 7.0.0: optimal solution; objective 7352.4
A19: 13873 simplex iterations | C19: 48305 simplex iterations | E19: 142936 simplex iterations | G19: 529184 simplex iterations | I19: 122695 simplex iterations | K19: 1650268 simplex iterations
A20: 1178 branch-and-cut nodes | C20: 6118 branch-and-cut nodes | E20: 16836 branch-and-cut nodes | G20: 55424 branch-and-cut nodes | I20: 12354 branch-and-cut nodes | K20: 217628 branch-and-cut nodes
... A25: 5 0 | C25: 5 0 | E25: 5 0 | G25: 5 0 | I25: 5 0 | K25: 5 0
A26: 42887 | C26: 6 0 | E26: 6 0 | G26: 6 0 | I26: 6 0 | K26: 6 0
A27: 7 0 | C27: 7 0 | E27: 7 0 | G27: 7 0 | I27: 7 0 | K27: 7 0
A28: 8 0 | C28: 8 0 | E28: 8 0 | G28: 8 0 | I28: 8 0 | K28: 8 0
A29: 9 0 | C29: 9 0 | E29: 9 0 | G29: 9 0 | I29: 9 0 | K29: 9 0
A30: 43010 | C30: 43009 | E30: 43009 | G30: 43009 | I30: 43009 | K30: 43010
A31: 43040 | C31: 43042 | E31: 11 0 | G31: 43042 | I31: 43042 | K31: 43040
A32: 12 0 | C32: 12 0 | E32: 12 0 | G32: 12 0 | I32: 12 0 | K32: 12 0
A33: 13 0 | C33: 13 0 | E33: 13 0 | G33: 13 0 | I33: 13 0 | K33: 13 0
A34: 14 0 | C34: 14 0 | E34: 14 0 | G34: 14 0 | I34: 14 0 | K34: 14 0
A35: 15 0 | C35: 15 0 | E35: 15 0 | G35: 15 0 | I35: 15 0 | K35: 15 0
A36: 16 0 | C36: 16 0 | E36: 16 0 | G36: 16 0 | I36: 16 0 | K36: 16 0
A37: 17 0 | C37: 17 0 | E37: 17 0 | G37: 17 0 | I37: 17 0 | K37: 17 0
A38: 18 0 | C38: 18 0 | E38: 18 0 | G38: 18 0 | I38: 18 0 | K38: 18 0
A39: 19 0 | C39: 19 0 | E39: 19 0 | G39: 19 0 | I39: 19 0 | K39: 19 0
A40: ; | C40: ; | E40: ; | G40: ; | I40: ; | K40: ;
A42: X [*] := | C42: X [*] := | E42: X [*] := | G42: X [*] := | I42: X [*] := | K42: X [*] :=
A43: 1 0 9 0 17 0 27 0 36 0 48 0 56 0 65 0 75 0 83 0 90 0 | C43: 1 0 9 0 17 0 27 0 36 0 48 0 56 0 65 0 75 0 83 0 90 0 | E43: 1 0 9 0 17 0 27 0 36 0 48 0 56 0 65 0 75 0 83 0 90 0 | G43: 1 0 9 0 17 0 27 0 36 1 48 0 56 0 65 0 75 0 83 0 90 0 | I43: 1 0 9 0 17 0 27 0 36 1 48 0 56 0 65 0 75 0 83 0 90 0 | K43: 1 0 9 0 17 0 27 0 36 1 48 0 56 0 65 0 75 0 83 0 90 0
A44: 2 0 10 0 18 0 28 0 38 0 49 0 57 0 67 0 77 0 84 2 91 0 | C44: 2 0 10 0 18 0 28 0 38 0 49 0 57 1 67 0 77 1 84 2 91 0 | E44: 2 0 10 0 18 0 28 0 38 0 49 0 57 0 67 0 77 1 84 2 91 0 | G44: 2 0 10 0 18 0 28 0 38 0 49 0 57 1 67 0 77 1 84 2 91 0 | I44: 2 0 10 0 18 0 28 0 38 0 49 0 57 1 67 0 77 1 84 3 91 0 | K44: 2 0 10 0 18 0 28 0 38 0 49 0 57 1 67 0 77 1 84 2 91 0
... A70: l = 6 | C70: k = 17 | E70: l = 6 | G70: k = 17 | I70: l = 6 | K70: i = 10
A71: h = 4 | B71: x2 | C71: V[k,l] = 387 | E71: h = 4 | G71: V[k,l] = 350 | I71: h = 4 | K71: U[i,j] = 904
A73: k = 6 | C73: k = 47 | E73: l = 6 | G73: l = 20 | I73: l = 6 | K73: l = 3
A74: V[k,l] = 700 | C74: V[k,l] = 63 | E74: h = 5 | G74: h = 2 | I74: h = 8 | K74: h = 2
A76: l = 17 | C76: l = 33 | E76: k = 6 | G76: k = 3 | I76: k = 6 | K76: k = 3
A77: h = 4 | C77: h = 2 | E77: V[k,l] = 750 | G77: V[k,l] = 74 | I77: V[k,l] = 884 | K77: V[k,l] = 85
A79: k = 17 | C79: k = 20 | E79: l = 17 | G79: k = 20 | I79: k = 22 | K79: k = 20
A80: V[k,l] = 328 | C80: V[k,l] = 30 | E80: h = 8 | G80: V[k,l] = 176 | I80: V[k,l] = 16 | K80: V[k,l] = 84
A82: k = 47 | C82: k = 33 | E82: k = 17 | G82: l = 47 | I82: l = 17 | K82: k = 46
...

Sheet bud=250
A1: Bud := 250; | B1: alp := 0.98; | C1: bet := 0.85;
A2: Gurobi 7.0.0: optimal solution; objective 5495.6
A3: 48305 simplex iterations
A4: 6118 branch-and-cut nodes
A5: i | B5: W [*] := | C5: Secondary expansion | G5: Cost_Sec = | H5: 71.7 | I5: $
A6: 1 | D6: Clayton Heights Secondary | G6: Cost_Ele = | H6: 178.1 | I6: $
A7: 2 | D7: Ecole Earl Marriott
A8: 3 | D8: Ecole Elgin Park | G8: Create_Sec = | H8: 1400 | I8: seats
A9: 4 | D9: Ecole Fraser Heights | G9: Create_Ele = | H9: 4150 | I9: seats
A10: 5 | D10: Ecole Kwantlen Park
A11: 6 | D11: Ecole Lord Tweedsmuir | G11: Overcrowd_Sec | H11: =0.457379*100 -> 45.7379 | I11: %
A12: 7 | D12: Ecole Panorama Ridge | G12: Overcrowd_Ele | H12: =0.455099*100 -> 45.5099 | I12: %
A13: 8 | D13: Enver Creek Secondary
A14: 9 | D14: Fleetwood Park Secondary
A15: 10 | B15: 1 | C15: 100 | D15: Frank Hurt Secondary
A16: 11 | B16: 3 | C16: 300 | D16: Guildford Park Secondary
A17: 12 | D17: Johnston Heights Secondary
A18: 13 | D18: L. A. Matheson Secondary
A19: 14 | D19: North Surrey Secondary
A20: 15 | D20: Princess Margaret Secondary
A21: 16 | D21: Queen Elizabeth Secondary
A22: 17 | D22: Semiahmoo Secondary
A23: 18 | D23: Sullivan Heights Secondary
A24: 19 | D24: Tamanawis Secondary
A25: ; | C25: =SUM(C6:C24) -> 400 | E25: Cost: | F25: =C25*2.9/100 -> 11.6
A27: k | B27: X [*] := | C27: Elementary expansion in hundreds
A28: 1 | D28: A. H. P. Matthew Elementary
A29: 2 | D29: A. J. McLellan Elementary
A30: 3 | D30: Adams Road Elementary
A31: 4 | D31: Bayridge Elementary
A32: 5 | D32: Bear Creek Elementary
A33: 6 | D33: Beaver Creek Elementary
A34: 7 | D34: Berkshire Park Elementary
A35: 8 | D35: Betty Huff Elementary
A36: 9 | D36: Bonaccord Elementary
A37: 10 | D37: Bothwell Elementary
A38: 11 | D38: Boundary Park Elementary
A39: 12 | D39: Bridgeview Elementary
... A46: 19 | D46: Clayton Elementary
A47: 20 | B47: 2 | C47: =B47*100 -> 200 | D47: Coast Meridian Elementary
...

Sheet bud=300
A1: Bud := 300; | B1: alp := 0.98; | C1: bet := 0.71;
A2: Gurobi 7.0.0: optimal solution; objective 6748.8
A3: 529184 simplex iterations
A4: 55424 branch-and-cut nodes
A5: i | B5: W [*] := | C5: Secondary expansion | G5: Cost_Sec = | H5: 71.7 | I5: $
A6: 1 | D6: Clayton Heights Secondary | G6: Cost_Ele = | H6: 228.1 | I6: $
A7: 2 | D7: Ecole Earl Marriott
A8: 3 | D8: Ecole Elgin Park | G8: Create_Sec = | H8: 1400 | I8: seats
A9: 4 | D9: Ecole Fraser Heights | G9: Create_Ele = | H9: 5400 | I9: seats
A10: 5 | D10: Ecole Kwantlen Park
A11: 6 | D11: Ecole Lord Tweedsmuir | G11: Overcrowd_Sec | H11: =0.457379*100 -> 45.7379 | I11: %
A12: 7 | D12: Ecole Panorama Ridge | G12: Overcrowd_Ele | H12: =0.410547*100 -> 41.0547 | I12: %
A13: 8 | D13: Enver Creek Secondary
A14: 9 | D14: Fleetwood Park Secondary
A15: 10 | B15: 1 | C15: 100 | D15: Frank Hurt Secondary
A16: 11 | B16: 3 | C16: 300 | D16: Guildford Park Secondary
A17: 12 | D17: Johnston Heights Secondary
A18: 13 | D18: L. A. Matheson Secondary
A19: 14 | D19: North Surrey Secondary
A20: 15 | D20: Princess Margaret Secondary
A21: 16 | D21: Queen Elizabeth Secondary
A22: 17 | D22: Semiahmoo Secondary
A23: 18 | D23: Sullivan Heights Secondary
A24: 19 | D24: Tamanawis Secondary
A25: ; | C25: =SUM(C6:C24) -> 400 | E25: Cost: | F25: =C25*2.9/100 -> 11.6
A27: k | B27: X [*] := | C27: Elementary expansion in hundreds
A28: 1 | D28: A. H. P. Matthew Elementary
A29: 2 | D29: A. J. McLellan Elementary
A30: 3 | D30: Adams Road Elementary
A31: 4 | D31: Bayridge Elementary
A32: 5 | D32: Bear Creek Elementary
A33: 6 | D33: Beaver Creek Elementary
A34: 7 | D34: Berkshire Park Elementary
A35: 8 | D35: Betty Huff Elementary
A36: 9 | D36: Bonaccord Elementary
A37: 10 | D37: Bothwell Elementary
A38: 11 | D38: Boundary Park Elementary
A39: 12 | D39: Bridgeview Elementary
... A46: 19 | D46: Clayton Elementary
A47: 20 | B47: 2 | C47: =B47*100 -> 200 | D47: Coast Meridian Elementary
...

Sheet bud=350
A1: Bud := 350; | B1: alp := 0.87; | C1: bet := 0.73;
A2: Gurobi 7.0.0: optimal solution; objective 7352.4
A3: 1650268 simplex iterations
A4: 217628 branch-and-cut nodes
A5: i | B5: W [*] := | C5: Secondary expansion | G5: Cost_Sec = | H5: 130.4 | I5: $
A6: 1 | D6: Clayton Heights Secondary | G6: Cost_Ele = | H6: 219.6 | I6: $
A7: 2 | D7: Ecole Earl Marriott
A8: 3 | D8: Ecole Elgin Park | G8: Create_Sec = | H8: 2300 | I8: seats
A9: 4 | D9: Ecole Fraser Heights | G9: Create_Ele = | H9: 5200 | I9: seats
A10: 5 | D10: Ecole Kwantlen Park
A11: 6 | D11: Ecole Lord Tweedsmuir | G11: Overcrowd_Sec | H11: =0.41071*100 -> 41.071 | I11: %
A12: 7 | D12: Ecole Panorama Ridge | G12: Overcrowd_Ele | H12: =0.417491*100 -> 41.7491 | I12: %
A13: 8 | D13: Enver Creek Secondary
A14: 9 | D14: Fleetwood Park Secondary
A15: 10 | B15: 2 | C15: =B15*100 -> 200 | D15: Frank Hurt Secondary
A16: 11 | B16: 1 | C16: =B16*100 -> 100 | D16: Guildford Park Secondary
A17: 12 | D17: Johnston Heights Secondary
A18: 13 | D18: L. A. Matheson Secondary
A19: 14 | D19: North Surrey Secondary
A20: 15 | D20: Princess Margaret Secondary
A21: 16 | D21: Queen Elizabeth Secondary
A22: 17 | D22: Semiahmoo Secondary
A23: 18 | D23: Sullivan Heights Secondary
A24: 19 | D24: Tamanawis Secondary
A25: ; | C25: =SUM(C6:C24) -> 300 | E25: Cost: | F25: =C25*2.9/100 -> 8.7
A27: k | B27: X [*] := | C27: Elementary expansion in hundreds
A28: 1 | D28: A. H. P. Matthew Elementary
A29: 2 | D29: A. J. McLellan Elementary
A30: 3 | D30: Adams Road Elementary
A31: 4 | D31: Bayridge Elementary
A32: 5 | D32: Bear Creek Elementary
A33: 6 | D33: Beaver Creek Elementary
A34: 7 | D34: Berkshire Park Elementary
A35: 8 | D35: Betty Huff Elementary
A36: 9 | D36: Bonaccord Elementary
A37: 10 | D37: Bothwell Elementary
A38: 11 | D38: Boundary Park Elementary
A39: 12 | D39: Bridgeview Elementary
... A46: 19 | D46: Clayton Elementary
A47: 20 | B47: 2 | C47: =B47*100 -> 200 | D47: Coast Meridian Elementary
...

Sheet AMPL .mod file
A1: set J; | C1: # | D1: Secondary school catchment zones
A2: set L; | C2: # | D2: Elementary school catchment zones
A3: set G; | C3: # | D3: Choices of capacity for a new secondary school
A4: set H; | C4: # | D4: Choices of capacity for a new elementary school
A6: param S {J} >= 0; | C6: # | D6: Secondary students population
A7: param c {J} >= 0; | C7: # | D7: Secondary school capacity
A8: param sig {J} >= 0; | C8: # | D8: Number of 100 seats expanding for secondary
A9: param tau {L} >= 0; | C9: # | D9: Number of 100 seats expanding for elementary
A10: param phi >= 0; | C10: # | D10: Cost for Expanding 100 seats for secondary
A11: param lam >= 0; | C11: # | D11: Cost for Expanding 100 seats for elementary
A12: param gam {G} >= 0; | C12: # | D12: Capacity for a new secondary school
A13: param a {J,J} >= 0; | C13: # | D13: Adjacencies for secondary catchment zones
... A20: param Bud >=0; | C20: # | D20: Total Budget
A21: param P {j in J} = S[j]-c[j];
A22: param Q {l in L} = E[l]-d[l];
A23: param alp >= 0;
A24: param bet >=0;
A26: set I := {j in J: P[j] > 0}; | C26: # | D26: Secondary zones that have overcap
A27: set K := {l in L: Q[l] > 0}; | C27: # | D27: Elementary zones that have overcap
A29: var W {j in I} integer >= 0; | C29: # | D29: Expansion for secondary
A30: var X {l in K} integer >=0; | C30: # | D30: Expansion for elementary
A31: var Y {j in I, g in G} integer >= 0; | C31: # | D31: Locations for new secondary
A32: var Z {l in K, h in H} integer >= 0; | C32: # | D32: Locations for new elementary
A33: var U {i in I, j in I} integer >= 0; | C33: # | D33: Transfers for new secondary
A34: var V {k in K, l in K} integer >= 0; | C34: # | D34: Transfers for new elementary
A36: maximize Crowdedness:
B37: sum {i in I} 100*W[i] + 0.9*sum {i in I,j in I} U[i,j] + 0.1*sum {i in I} U[i,i] + sum {k in K} 100*X[k] + 0.9*sum {k in K,l in K} V[k,l] + 0.1*sum {k in K} V[k,k];
A39: subject to Lowerbd_Sec {i in I}:
B40: sum {j in I} U[i,j] <= P[i] - 100*W[i];
A41: subject to Lowerbd_Ele {k in K}:
B42: sum {l in K} V[k,l] <= Q[k] - 100*X[k];
A44: subject to Upperbd_Sec {i in I}:
B45: S[i] - sum {j in I} U[i,j] <= (1+alp)*(c[i] + 100*W[i]);
A46: subject to Upperbd_Ele {k in K}:
B47: E[k] - sum {l in K} V[k,l] <= (1+bet)*(d[k] + 100*X[k]);
A49: subject to Expan_Sec {i in I}:
B50: 100*W[i] <= sig[i]-c[i];
A51: subject to Expan_Ele {k in K}:
B52: 100*X[k] <= tau[k]-d[k];
A54: subject to Adjacent_Sec {i in I, j in I}:
...

Sheet All data
A2: Secondary School | B2: Index | C2: Population 2025 | D2: Capacity | E2: Max Capacity | H2: {=TRANSPOSE(G3:G21)} -> Clayton Heights Secondary | I2: Ecole Earl Marriott | J2: Ecole Elgin Park | K2: Ecole Fraser Heights | L2: Ecole Kwantlen Park | M2: Ecole Lord Tweedsmuir | N2: Ecole Panorama Ridge | O2: Enver Creek Secondary | P2: Fleetwood Park Secondary | Q2: Frank Hurt Secondary | R2: Guildford Park Secondary | S2: Johnston Heights Secondary | T2: L. A. Matheson Secondary | U2: North Surrey Secondary | V2: Princess Margaret Secondary | W2: Queen Elizabeth Secondary | X2: Semiahmoo Secondary | Y2: Sullivan Heights Secondary | Z2: Tamanawis Secondary
A3: Clayton Heights Secondary | B3: 1 | C3: 3049 | D3: 2580 | E3: 3000 | G3: Clayton Heights Secondary | H3: 1 | I3: 0 | J3: 0 | K3: 0 | L3: 0 | M3: 1 | N3: 0 | O3: 0 | P3: 0 | Q3: 0 | R3: 0 | S3: 0 | T3: 0 | U3: 0 | V3: 0 | W3: 0 | X3: 0 | Y3: 0 | Z3: 0
A4: Ecole Earl Marriott | B4: 2 | C4: 2826 | D4: 3000 | E4: 3000 | G4: Ecole Earl Marriott | H4: 0 | I4: 1 | J4: 0 | K4: 0 | L4: 0 | M4: 0 | N4: 0 | O4: 0 | P4: 0 | Q4: 0 | R4: 0 | S4: 0 | T4: 0 | U4: 0 | V4: 0 | W4: 0 | X4: 1 | Y4: 0 | Z4: 0
A5: Ecole Elgin Park | B5: 3 | C5: 1504 | D5: 1200 | E5: 1500 | G5: Ecole Elgin Park | H5: 0 | I5: 0 | J5: 1 | K5: 0 | L5: 0 | M5: 0 | N5: 1 | O5: 0 | P5: 0 | Q5: 0 | R5: 0 | S5: 0 | T5: 0 | U5: 0 | V5: 0 | W5: 0 | X5: 1 | Y5: 1 | Z5: 0
A6: Ecole Fraser Heights | B6: 4 | C6: 2115 | D6: 1300 | E6: 1300 | G6: Ecole Fraser Heights | H6: 0 | I6: 0 | J6: 0 | K6: 1 | L6: 0 | M6: 0 | N6: 0 | O6: 0 | P6: 0 | Q6: 0 | R6: 1 | S6: 1 | T6: 0 | U6: 1 | V6: 0 | W6: 0 | X6: 0 | Y6: 0 | Z6: 0
A7: Ecole Kwantlen Park | B7: 5 | C7: 1947 | D7: 1200 | E7: 1500 | G7: Ecole Kwantlen Park | H7: 0 | I7: 0 | J7: 0 | K7: 0 | L7: 1 | M7: 0 | N7: 0 | O7: 0 | P7: 0 | Q7: 0 | R7: 1 | S7: 0 | T7: 1 | U7: 0 | V7: 0 | W7: 1 | X7: 0 | Y7: 0 | Z7: 0
A8: Ecole Lord Tweedsmuir | B8: 6 | C8: 2714 | D8: 1400 | E8: 1500 | G8: Ecole Lord Tweedsmuir | H8: 1 | I8: 0 | J8: 0 | K8: 0 | L8: 0 | M8: 1 | N8: 0 | O8: 0 | P8: 1 | Q8: 1 | R8: 0 | S8: 0 | T8: 0 | U8: 1 | V8: 0 | W8: 0 | X8: 0 | Y8: 1 | Z8: 0
A9: Ecole Panorama Ridge | B9: 7 | C9: 1771 | D9: 1525 | E9: 1525 | G9: Ecole Panorama Ridge | H9: 0 | I9: 0 | J9: 1 | K9: 0 | L9: 0 | M9: 0 | N9: 1 | O9: 0 | P9: 0 | Q9: 1 | R9: 0 | S9: 0 | T9: 0 | U9: 0 | V9: 1 | W9: 0 | X9: 0 | Y9: 1 | Z9: 1
A10: Enver Creek Secondary | B10: 8 | C10: 1771 | D10: 1400 | E10: 1500 | G10: Enver Creek Secondary | H10: 0 | I10: 0 | J10: 0 | K10: 0 | L10: 0 | M10: 0 | N10: 0 | O10: 1 | P10: 1 | Q10: 1 | R10: 1 | S10: 1 | T10: 0 | U10: 0 | V10: 0 | W10: 1 | X10: 0 | Y10: 0 | Z10: 0
A11: Fleetwood Park Secondary | B11: 9 | C11: 1477 | D11: 1200 | E11: 1500 | G11: Fleetwood Park Secondary | H11: 0 | I11: 0 | J11: 0 | K11: 0 | L11: 0 | M11: 1 | N11: 0 | O11: 1 | P11: 1 | Q11: 1 | R11: 0 | S11: 1 | T11: 0 | U11: 1 | V11: 0 | W11: 0 | X11: 0 | Y11: 0 | Z11: 0
A12: Frank Hurt Secondary | B12: 10 | C12: 3501 | D12: 1200 | E12: 1500 | F12: =C12-D12 -> 2301 | G12: Frank Hurt Secondary | H12: 0 | I12: 0 | J12: 0 | K12: 0 | L12: 0 | M12: 1 | N12: 1 | O12: 1 | P12: 1 | Q12: 1 | R12: 0 | S12: 0 | T12: 0 | U12: 0 | V12: 1 | W12: 1 | X12: 0 | Y12: 1 | Z12: 0
A13: Guildford Park Secondary | B13: 11 | C13: 2532 | D13: 1050 | E13: 1500 | G13: Guildford Park Secondary | H13: 0 | I13: 0 | J13: 0 | K13: 1 | L13: 1 | M13: 0 | N13: 0 | O13: 1 | P13: 0 | Q13: 0 | R13: 1 | S13: 1 | T13: 0 | U13: 0 | V13: 0 | W13: 1 | X13: 0 | Y13: 0 | Z13: 0
A14: Johnston Heights Secondary | B14: 12 | C14: 1866 | D14: 1450 | E14: 1500 | G14: Johnston Heights Secondary | H14: 0 | I14: 0 | J14: 0 | K14: 1 | L14: 0 | M14: 0 | N14: 0 | O14: 1 | P14: 1 | Q14: 0 | R14: 1 | S14: 1 | T14: 0 | U14: 1 | V14: 0 | W14: 0 | X14: 0 | Y14: 0 | Z14: 0
A15: L. A. Matheson Secondary | B15: 13 | C15: 2223 | D15: 1400 | E15: 1500 | G15: L. A. Matheson Secondary | H15: 0 | I15: 0 | J15: 0 | K15: 0 | L15: 1 | M15: 0 | N15: 0 | O15: 0 | P15: 0 | Q15: 0 | R15: 0 | S15: 0 | T15: 1 | U15: 0 | V15: 1 | W15: 1 | X15: 0 | Y15: 0 | Z15: 0
A16: North Surrey Secondary | B16: 14 | C16: 2961 | D16: 1500 | E16: 1500 | G16: North Surrey Secondary | H16: 0 | I16: 0 | J16: 0 | K16: 1 | L16: 0 | M16: 1 | N16: 0 | O16: 0 | P16: 1 | Q16: 0 | R16: 0 | S16: 1 | T16: 0 | U16: 1 | V16: 0 | W16: 0 | X16: 0 | Y16: 0 | Z16: 0
A17: Princess Margaret Secondary | B17: 15 | C17: 2220 | D17: 1500 | E17: 1500 | G17: Princess Margaret Secondary | H17: 0 | I17: 0 | J17: 0 | K17: 0 | L17: 0 | M17: 0 | N17: 1 | O17: 0 | P17: 0 | Q17: 1 | R17: 0 | S17: 0 | T17: 1 | U17: 0 | V17: 1 | W17: 1 | X17: 0 | Y17: 1 | Z17: 1
A18: Queen Elizabeth Secondary | B18: 16 | C18: 2539 | D18: 1400 | E18: 1500 | G18: Queen Elizabeth Secondary | H18: 0 | I18: 0 | J18: 0 | K18: 0 | L18: 1 | M18: 0 | N18: 0 | O18: 1 | P18: 0 | Q18: 1 | R18: 1 | S18: 0 | T18: 1 | U18: 0 | V18: 1 | W18: 1 | X18: 0 | Y18: 0 | Z18: 0
A19: Semiahmoo Secondary | B19: 17 | C19: 1320 | D19: 1300 | E19: 1500 | G19: Semiahmoo Secondary | H19: 0 | I19: 1 | J19: 1 | K19: 0 | L19: 0 | M19: 0 | N19: 0 | O19: 0 | P19: 0 | Q19: 0 | R19: 0 | S19: 0 | T19: 0 | U19: 0 | V19: 0 | W19: 0 | X19: 1 | Y19: 1 | Z19: 0
A20: Sullivan Heights Secondary | B20: 18 | C20: 1732 | D20: 1700 | E20: 1700 | G20: Sullivan Heights Secondary | H20: 0 | I20: 0 | J20: 1 | K20: 0 | L20: 0 | M20: 1 | N20: 1 | O20: 0 | P20: 0 | Q20: 1 | R20: 0 | S20: 0 | T20: 0 | U20: 0 | V20: 1 | W20: 0 | X20: 1 | Y20: 1 | Z20: 0
A21: Tamanawis Secondary | B21: 19 | C21: 2406 | D21: 1500 | E21: 1500 | G21: Tamanawis Secondary | H21: 0 | I21: 0 | J21: 0 | K21: 0 | L21: 0 | M21: 0 | N21: 1 | O21: 0 | P21: 0 | Q21: 0 | R21: 0 | S21: 0 | T21: 0 | U21: 0 | V21: 1 | W21: 0 | X21: 0 | Y21: 0 | Z21: 1
C22: =SUM(C3:C21) -> 42474 | D22: =SUM(D3:D21) -> 28805
A23: Elementary School | B23: Index | C23: Population 2025 | D23: Capacity | E23: Max Capacity | H23: {=TRANSPOSE(G24:G119)} -> A. H. P. Matthew Elementary | I23: A. J. McLellan Elementary | J23: Adams Road Elementary | K23: Bayridge Elementary | L23: Bear Creek Elementary | M23: Beaver Creek Elementary | N23: Berkshire Park Elementary | O23: Betty Huff Elementary | P23: Bonaccord Elementary | Q23: Bothwell Elementary | R23: Boundary Park Elementary | S23: Bridgeview Elementary | T23: Brookside Elementary | U23: Cambridge Elementary | V23: Cedar Hills Elementary | W23: Chantrell Creek Elementary | X23: Chimney Hill Elementary | Y23: Cindrich Elementary | Z23: Clayton Elementary | AA23: Coast Meridian Elementary | AB23: Colebrook Elementary | AC23: Cougar Creek Elementary | AD23: Coyote Creek Elementary | AE23: Creekside Elementary | AF23: David Brankin Elementary | AG23: Dogwood Elementary | AH23: Don Christian Elementary | AI23: Dr. F. D. Sinclair Elementary | AJ23: East Kensington Elementary | AK23: École Crescent Park | AL23: École Erma Stephenson | AM23: École Fraser Wood | AN23: École Frost Road | AO23: École Henry Bose | AP23: École Jessie Lee | AQ23: École K.B. Woodward | AR23: École Martha Currie | AS23: École Ocean Cliff | AT23: École Peace Arch | AU23: École Riverdale | AV23: École Simon Cunningham | AW23: École Sunrise Ridge | AX23: École Woodward Hill | AY23: Ellendale Elementary | AZ23: Forsyth Road Elementary | BA23: George Greenaway Elementary | BB23: Georges Vanier Elementary | BC23: Goldstone Park Elementary | BD23: Green Timbers Elementary | BE23: H. T. Thrift Elementary | BF23: Hall's Prairie Elementary | BG23: Harold Bishop Elementary | BH23: Hazelgrove Elementary | BI23: Hillcrest Elementary | BJ23: Hjorth Road Elementary | BK23: Holly Elementary | BL23: Hyland Elementary | BM23: J. T. Brown Elementary | BN23: James Ardiel Elementary | BO23: Janice Churchill Elementary | BP23: Katzie Elementary | BQ23: Kennedy Trail Elementary | BR23: Kirkbride Elementary | BS23: Latimer Road Elementary | BT23: Lena Shaw Elementary | BU23: M. B. Sanford Elementary | BV23: Maple Green Elementary | BW23: Martha Jane Norris Elementary | BX23: Mary Jane Shannon Elementary | BY23: Morgan Elementary | BZ23: Newton Elementary | CA23: North Ridge Elementary | CB23: Old Yale Road Elementary | CC23: Pacific Heights Elementary | CD23: Panorama Park Elementary | CE23: Port Kells Elementary | CF23: Prince Charles Elementary | CG23: Ray Shepherd Elementary | CH23: Rosemary Heights Elementary | CI23: Royal Heights Elementary | CJ23: Semiahmoo Trail Elementary | CK23: Senator Reid Elementary | CL23: Serpentine Heights Elementary | CM23: South Meridian Elementary | CN23: Strawberry Hill Elementary | CO23: Sullivan Elementary | CP23: Sunnyside Elementary | CQ23: Surrey Centre Elementary | CR23: T. E. Scott Elementary | CS23: W. E. Kinvig Elementary | CT23: Walnut Road Elementary | CU23: Westerman Elementary | CV23: White Rock Elementary | CW23: William F. Davidson Elementary | CX23: William Watson Elementary | CY23: Woodland Park Elementary
A24: A. H. P. Matthew Elementary | B24: 1 | C24: 640 | D24: 410 | E24: 600 | G24: A. H. P. Matthew Elementary | H24: 1 | I24: 0 | J24: 0 | K24: 0 | L24: 0 | M24: 0 | N24: 0 | O24: 1 | P24: 0 | Q24: 0 | R24: 0 | S24: 0 | T24: 0 | U24: 0 | V24: 1 | W24: 0 | X24: 0 | Y24: 1 | Z24: 0 | AA24: 0 | AB24: 0 | AC24: 0 | AD24: 0 | AE24: 0 | AF24: 0 | AG24: 0 | AH24: 0 | AI24: 0 | AJ24: 0 | AK24: 0 | AL24: 0 | AM24: 0 | AN24: 0 | AO24: 0 | AP24: 0 | AQ24: 0 | AR24: 0 | AS24: 0 | AT24: 0 | AU24: 0 | AV24: 1 | AW24: 0 | AX24: 0 | AY24: 0 | AZ24: 0 | BA24: 0 | BB24: 0 | BC24: 0 | BD24: 0 | BE24: 0 | BF24: 0 | BG24: 0 | BH24: 0 | BI24: 0 | BJ24: 0 | BK24: 0 | BL24: 0 | BM24: 0 | BN24: 0 | BO24: 0 | BP24: 0 | BQ24: 0 | BR24: 0 | BS24: 0 | BT24: 1 | BU24: 0 | BV24: 0 | BW24: 0 | BX24: 0 | BY24: 0 | BZ24: 0 | CA24: 0 | CB24: 1 | CC24: 0 | CD24: 0 | CE24: 0 | CF24: 1 | CG24: 0 | CH24: 0 | CI24: 0 | CJ24: 0 | CK24: 1 | CL24: 0 | CM24: 0 | CN24: 0 | CO24: 0 | CP24: 0 | CQ24: 0 | CR24: 0 | CS24: 0 | CT24: 0 | CU24: 0 | CV24: 0 | CW24: 0 | CX24: 0 | CY24: 0
A25: A. J. McLellan Elementary | B25: 2 | C25: 816 | D25: 505 | E25: 600 | G25: A. J. McLellan Elementary | H25: 0 | I25: 1 | J25: 0 | K25: 0 | L25: 0 | M25: 0 | N25: 0 | O25: 0 | P25: 0 | Q25: 0 | R25: 0 | S25: 0 | T25: 0 | U25: 0 | V25: 0 | W25: 0 | X25: 0 | Y25: 0 | Z25: 0 | AA25: 0 | AB25: 0 | AC25: 0 | AD25: 1 | AE25: 0 | AF25: 0 | AG25: 0 | AH25: 0 | AI25: 0 | AJ25: 0 | AK25: 0 | AL25: 0 | AM25: 0 | AN25: 0 | AO25: 0 | AP25: 0 | AQ25: 0 | AR25: 0 | AS25: 0 | AT25: 0 | AU25: 0 | AV25: 0 | AW25: 0 | AX25: 0 | AY25: 0 | AZ25: 0 | BA25: 1 | BB25: 0 | BC25: 0 | BD25: 0 | BE25: 0 | BF25: 0 | BG25: 0 | BH25: 0 | BI25: 0 | BJ25: 0 | BK25: 0 | BL25: 0 | BM25: 0 | BN25: 0 | BO25: 0 | BP25: 0 | BQ25: 0 | BR25: 0 | BS25: 0 | BT25: 0 | BU25: 0 | BV25: 0 | BW25: 0 | BX25: 0 | BY25: 0 | BZ25: 0 | CA25: 0 | CB25: 0 | CC25: 0 | CD25: 0 | CE25: 0 | CF25: 0 | CG25: 0 | CH25: 0 | CI25: 0 | CJ25: 0 | CK25: 0 | CL25: 0 | CM25: 0 | CN25: 0 | CO25: 1 | CP25: 0 | CQ25: 1 | CR25: 1 | CS25: 0 | CT25: 0 | CU25: 0 | CV25: 0 | CW25: 0 | CX25: 1 | CY25: 0
A26: Adams Road Elementary | B26: 3 | C26: 980 | D26: 530 | E26: 530 | G26: Adams Road Elementary | H26: 0 | I26: 0 | J26: 1 | K26: 0 | L26: 0 | M26: 0 | N26: 0 | O26: 0 | P26: 0 | Q26: 0 | R26: 0 | S26: 0 | T26: 0 | U26: 0 | V26: 0 | W26: 0 | X26: 0 | Y26: 0 | Z26: 1 | AA26: 1 | AB26: 0 | AC26: 0 | AD26: 0 | AE26: 0 | AF26: 0 | AG26: 0 | AH26: 1 | AI26: 0 | AJ26: 0 | AK26: 0 | AL26: 0 | AM26: 0 | AN26: 0 | AO26: 0 | AP26: 0 | AQ26: 0 | AR26: 0 | AS26: 0 | AT26: 0 | AU26: 0 | AV26: 0 | AW26: 0 | AX26: 0 | AY26: 0 | AZ26: 0 | BA26: 1 | BB26: 0 | BC26: 0 | BD26: 0 | BE26: 0 | BF26: 0 | BG26: 0 | BH26: 0 | BI26: 1 | BJ26: 0 | BK26: 0 | BL26: 0 | BM26: 0 | BN26: 0 | BO26: 0 | BP26: 0 | BQ26: 0 | BR26: 0 | BS26: 0 | BT26: 0 | BU26: 0 | BV26: 0 | BW26: 0 | BX26: 0 | BY26: 0 | BZ26: 0 | CA26: 0 | CB26: 0 | CC26: 0 | CD26: 0 | CE26: 0 | CF26: 0 | CG26: 0 | CH26: 0 | CI26: 0 | CJ26: 0 | CK26: 0 | CL26: 0 | CM26: 0 | CN26: 0 | CO26: 0 | CP26: 0 | CQ26: 0 | CR26: 0 | CS26: 0 | CT26: 0 | CU26: 0 | CV26: 0 | CW26: 0 | CX26: 1 | CY26: 0
A27: Bayridge Elementary | B27: 4 | C27: 427 | D27: 320 | E27: 600 | G27: Bayridge Elementary | H27: 0 | I27: 0 | J27: 0 | K27: 1 | L27: 0 | M27: 0 | N27: 0 | O27: 0 | P27: 0 | Q27: 0 | R27: 0 | S27: 0 | T27: 0 | U27: 0 | V27: 0 | W27: 1 | X27: 0 | Y27: 0 | Z27: 0 | AA27: 0 | AB27: 0 | AC27: 0 | AD27: 0 | AE27: 0 | AF27: 0 | AG27: 0 | AH27: 0 | AI27: 0 | AJ27: 0 | AK27: 0 | AL27: 0 | AM27: 0 | AN27: 0 | AO27: 0 | AP27: 0 | AQ27: 0 | AR27: 0 | AS27: 0 | AT27: 0 | AU27: 0 | AV27: 0 | AW27: 0 | AX27: 0 | AY27: 0 | AZ27: 0 | BA27: 0 | BB27: 0 | BC27: 0 | BD27: 0 | BE27: 1 | BF27: 0 | BG27: 0 | BH27: 0 | BI27: 0 | BJ27: 0 | BK27: 0 | BL27: 0 | BM27: 0 | BN27: 0 | BO27: 0 | BP27: 0 | BQ27: 0 | BR27: 0 | BS27: 0 | BT27: 0 | BU27: 0 | BV27: 0 | BW27: 0 | BX27: 0 | BY27: 0 | BZ27: 0 | CA27: 0 | CB27: 0 | CC27: 0 | CD27: 0 | CE27: 0 | CF27: 0 | CG27: 1 | CH27: 0 | CI27: 0 | CJ27: 1 | CK27: 0 | CL27: 0 | CM27: 0 | CN27: 0 | CO27: 0 | CP27: 0 | CQ27: 0 | CR27: 0 | CS27: 0 | CT27: 0 | CU27: 0 | CV27: 0 | CW27: 0 | CX27: 0 | CY27: 0
A28: Bear Creek Elementary | B28: 5 | C28: 1036 | D28: 590 | E28: 600 | G28: Bear Creek Elementary | H28: 0 | I28: 0 | J28: 0 | K28: 0 | L28: 1 | M28: 0 | N28: 0 | O28: 0 | P28: 0 | Q28: 0 | R28: 0 | S28: 0 | T28: 1 | U28: 0 | V28: 0 | W28: 0 | X28: 0 | Y28: 1 | Z28: 0 | AA28: 0 | AB28: 0 | AC28: 0 | AD28: 0 | AE28: 1 | AF28: 1 | AG28: 0 | AH28: 0 | AI28: 0 | AJ28: 0 | AK28: 0 | AL28: 0 | AM28: 0 | AN28: 0 | AO28: 0 | AP28: 0 | AQ28: 0 | AR28: 0 | AS28: 0 | AT28: 0 | AU28: 0 | AV28: 1 | AW28: 0 | AX28: 0 | AY28: 0 | AZ28: 0 | BA28: 0 | BB28: 1 | BC28: 0 | BD28: 0 | BE28: 0 | BF28: 0 | BG28: 0 | BH28: 0 | BI28: 0 | BJ28: 0 | BK28: 0 | BL28: 0 | BM28: 0 | BN28: 0 | BO28: 0 | BP28: 0 | BQ28: 0 | BR28: 0 | BS28: 0 | BT28: 0 | BU28: 1 | BV28: 0 | BW28: 0 | BX28: 0 | BY28: 0 | BZ28: 1 | CA28: 0 | CB28: 0 | CC28: 0 | CD28: 0 | CE28: 0 | CF28: 0 | CG28: 0 | CH28: 0 | CI28: 0 | CJ28: 0 | CK28: 0 | CL28: 0 | CM28: 0 | CN28: 0 | CO28: 0 | CP28: 0 | CQ28: 0 | CR28: 0 | CS28: 1 | CT28: 0 | CU28: 0 | CV28: 0 | CW28: 0 | CX28: 0 | CY28: 0
A29: Beaver Creek Elementary | B29: 6 | C29: 1697 | D29: 515 | E29: 600 | G29: Beaver Creek Elementary | H29: 0 | I29: 0 | J29: 0 | K29: 0 | L29: 0 | M29: 1 | N29: 0 | O29: 0 | P29: 0 | Q29: 0 | R29: 1 | S29: 0 | T29: 0 | U29: 1 | V29: 0 | W29: 0 | X29: 0 | Y29: 0 | Z29: 0 | AA29: 0 | AB29: 0 | AC29: 1 | AD29: 0 | AE29: 0 | AF29: 0 | AG29: 0 | AH29: 0 | AI29: 0 | AJ29: 0 | AK29: 0 | AL29: 0 | AM29: 0 | AN29: 0 | AO29: 0 | AP29: 0 | AQ29: 0 | AR29: 0 | AS29: 0 | AT29: 0 | AU29: 0 | AV29: 0 | AW29: 0 | AX29: 0 | AY29: 0 | AZ29: 0 | BA29: 0 | BB29: 0 | BC29: 0 | BD29: 0 | BE29: 0 | BF29: 0 | BG29: 0 | BH29: 0 | BI29: 0 | BJ29: 0 | BK29: 0 | BL29: 0 | BM29: 1 | BN29: 0 | BO29: 0 | BP29: 0 | BQ29: 0 | BR29: 0 | BS29: 0 | BT29: 0 | BU29: 0 | BV29: 0 | BW29: 1 | BX29: 0 | BY29: 0 | BZ29: 0 | CA29: 0 | CB29: 0 | CC29: 0 | CD29: 0 | CE29: 0 | CF29: 0 | CG29: 0 | CH29: 0 | CI29: 0 | CJ29: 0 | CK29: 0 | CL29: 0 | CM29: 0 | CN29: 0 | CO29: 0 | CP29: 0 | CQ29: 0 | CR29: 0 | CS29: 0 | CT29: 0 | CU29: 0 | CV29: 0 | CW29: 0 | CX29: 0 | CY29: 0
A30: Berkshire Park Elementary | B30: 7 | C30: 503 | D30: 540 | E30: 600 | G30: Berkshire Park Elementary | H30: 0 | I30: 0 | J30: 0 | K30: 0 | L30: 0 | M30: 0 | N30: 1 | O30: 0 | P30: 1 | Q30: 0 | R30: 0 | S30: 0 | T30: 0 | U30: 0 | V30: 0 | W30: 0 | X30: 0 | Y30: 0 | Z30: 0 | AA30: 0 | AB30: 0 | AC30: 0 | AD30: 1 | AE30: 0 | AF30: 0 | AG30: 0 | AH30: 0 | AI30: 0 | AJ30: 0 | AK30: 0 | AL30: 0 | AM30: 0 | AN30: 0 | AO30: 0 | AP30: 0 | AQ30: 0 | AR30: 0 | AS30: 0 | AT30: 0 | AU30: 0 | AV30: 0 | AW30: 0 | AX30: 0 | AY30: 0 | AZ30: 0 | BA30: 0 | BB30: 0 | BC30: 0 | BD30: 1 | BE30: 0 | BF30: 0 | BG30: 0 | BH30: 0 | BI30: 0 | BJ30: 0 | BK30: 0 | BL30: 0 | BM30: 0 | BN30: 0 | BO30: 0 | BP30: 0 | BQ30: 0 | BR30: 0 | BS30: 0 | BT30: 0 | BU30: 0 | BV30: 0 | BW30: 0 | BX30: 0 | BY30: 0 | BZ30: 0 | CA30: 0 | CB30: 0 | CC30: 0 | CD30: 0 | CE30: 0 | CF30: 0 | CG30: 0 | CH30: 0 | CI30: 0 | CJ30: 0 | CK30: 0 | CL30: 0 | CM30: 0 | CN30: 0 | CO30: 0 | CP30: 0 | CQ30: 0 | CR30: 0 | CS30: 0 | CT30: 1 | CU30: 0 | CV30: 0 | CW30: 1 | CX30: 0 | CY30: 1
A31: Betty Huff Elementary | B31: 8 | C31: 664 | D31: 540 | E31: 600 | G31: Betty Huff Elementary | H31: 1 | I31: 0 | J31: 0 | K31: 0 | L31: 0 | M31: 0 | N31: 0 | O31: 1 | P31: 0 | Q31: 0 | R31: 0 | S31: 0 | T31: 0 | U31: 0 | V31: 1 | W31: 0 | X31: 0 | Y31: 1 | Z31: 0 | AA31: 0 | AB31: 0 | AC31: 0 | AD31: 0 | AE31: 0 | AF31: 1 | AG31: 0 | AH31: 0 | AI31: 0 | AJ31: 0 | AK31: 0 | AL31: 0 | AM31: 0 | AN31: 0 | AO31: 0 | AP31: 0 | AQ31: 0 | AR31: 0 | AS31: 0 | AT31: 0 | AU31: 0 | AV31: 0 | AW31: 0 | AX31: 0 | AY31: 0 | AZ31: 0 | BA31: 0 | BB31: 0 | BC31: 0 | BD31: 0 | BE31: 0 | BF31: 0 | BG31: 0 | BH31: 0 | BI31: 0 | BJ31: 0 | BK31: 0 | BL31: 0 | BM31: 0 | BN31: 0 | BO31: 0 | BP31: 0 | BQ31: 0 | BR31: 0 | BS31: 0 | BT31: 0 | BU31: 0 | BV31: 0 | BW31: 0 | BX31: 0 | BY31: 0 | BZ31: 0 | CA31: 0 | CB31: 0 | CC31: 0 | CD31: 0 | CE31: 0 | CF31: 0 | CG31: 0 | CH31: 0 | CI31: 0 | CJ31: 0 | CK31: 1 | CL31: 0 | CM31: 0 | CN31: 0 | CO31: 0 | CP31: 0 | CQ31: 0 | CR31: 0 | CS31: 0 | CT31: 0 | CU31: 0 | CV31: 0 | CW31: 0 | CX31: 0 | CY31: 0
A32: Bonaccord Elementary | B32: 9 | C32: 694 | D32: 590 | E32: 600 | G32: Bonaccord Elementary | H32: 0 | I32: 0 | J32: 0 | K32: 0 | L32: 0 | M32: 0 | N32: 1 | O32: 0 | P32: 1 | Q32: 0 | R32: 0 | S32: 0 | T32: 0 | U32: 0 | V32: 0 | W32: 0 | X32: 0 | Y32: 0 | Z32: 0 | AA32: 0 | AB32: 0 | AC32: 0 | AD32: 0 | AE32: 0 | AF32: 0 | AG32: 0 | AH32: 0 | AI32: 0 | AJ32: 0 | AK32: 0 | AL32: 0 | AM32: 0 | AN32: 0 | AO32: 0 | AP32: 0 | AQ32: 0 | AR32: 0 | AS32: 0 | AT32: 0 | AU32: 0 | AV32: 0 | AW32: 0 | AX32: 0 | AY32: 0 | AZ32: 0 | BA32: 0 | BB32: 0 | BC32: 0 | BD32: 1 | BE32: 0 | BF32: 0 | BG32: 1 | BH32: 0 | BI32: 0 | BJ32: 1 | BK32: 0 | BL32: 0 | BM32: 0 | BN32: 0 | BO32: 0 | BP32: 0 | BQ32: 0 | BR32: 0 | BS32: 0 | BT32: 1 | BU32: 0 | BV32: 0 | BW32: 0 | BX32: 0 | BY32: 0 | BZ32: 0 | CA32: 0 | CB32: 0 | CC32: 0 | CD32: 0 | CE32: 0 | CF32: 0 | CG32: 0 | CH32: 0 | CI32: 0 | CJ32: 0 | CK32: 0 | CL32: 0 | CM32: 0 | CN32: 0 | CO32: 0 | CP32: 0 | CQ32: 0 | CR32: 0 | CS32: 0 | CT32: 0 | CU32: 0 | CV32: 0 | CW32: 1 | CX32: 0 | CY32: 0
A33: Bothwell Elementary | B33: 10 | C33: 484 | D33: 315 | E33: 600 | G33: Bothwell Elementary | H33: 0 | I33: 0 | J33: 0 | K33: 0 | L33: 0 | M33: 0 | N33: 0 | O33: 0 | P33: 0 | Q33: 1 | R33: 0 | S33: 0 | T33: 0 | U33: 0 | V33: 0 | W33: 0 | X33: 0 | Y33: 0 | Z33: 0 | AA33: 0 | AB33: 0 | AC33: 0 | AD33: 0 | AE33: 0 | AF33: 0 | AG33: 0 | AH33: 0 | AI33: 0 | AJ33: 0 | AK33: 0 | AL33: 0 | AM33: 1 | AN33: 0 | AO33: 0 | AP33: 0 | AQ33: 0 | AR33: 0 | AS33: 0 | AT33: 0 | AU33: 0 | AV33: 0 | AW33: 0 | AX33: 0 | AY33: 0 | AZ33: 0 | BA33: 0 | BB33: 0 | BC33: 0 | BD33: 0 | BE33: 0 | BF33: 0 | BG33: 0 | BH33: 0 | BI33: 0 | BJ33: 0 | BK33: 0 | BL33: 0 | BM33: 0 | BN33: 0 | BO33: 0 | BP33: 0 | BQ33: 0 | BR33: 0 | BS33: 0 | BT33: 0 | BU33: 0 | BV33: 0 | BW33: 0 | BX33: 0 | BY33: 0 | BZ33: 0 | CA33: 0 | CB33: 0 | CC33: 0 | CD33: 0 | CE33: 1 | CF33: 0 | CG33: 0 | CH33: 0 | CI33: 0 | CJ33: 0 | CK33: 0 | CL33: 1 | CM33: 0 | CN33: 0 | CO33: 0 | CP33: 0 | CQ33: 0 | CR33: 0 | CS33: 0 | CT33: 0 | CU33: 0 | CV33: 0 | CW33: 0 | CX33: 0 | CY33: 0
A34: Boundary Park Elementary | B34: 11 | C34: 341 | D34: 340 | E34: 600 | G34: Boundary Park Elementary | H34: 0 | I34: 0 | J34: 0 | K34: 0 | L34: 0 | M34: 1 | N34: 0 | O34: 0 | P34: 0 | Q34: 0 | R34: 1 | S34: 0 | T34: 0 | U34: 0 | V34: 0 | W34: 0 | X34: 0 | Y34: 0 | Z34: 0 | AA34: 0 | AB34: 1 | AC34: 0 | AD34: 0 | AE34: 0 | AF34: 0 | AG34: 0 | AH34: 0 | AI34: 0 | AJ34: 0 | AK34: 0 | AL34: 0 | AM34: 0 | AN34: 0 | AO34: 0 | AP34: 0 | AQ34: 0 | AR34: 0 | AS34: 0 | AT34: 0 | AU34: 0 | AV34: 0 | AW34: 0 | AX34: 0 | AY34: 0 | AZ34: 0 | BA34: 0 | BB34: 0 | BC34: 0 | BD34: 0 | BE34: 0 | BF34: 0 | BG34: 0 | BH34: 0 | BI34: 0 | BJ34: 0 | BK34: 0 | BL34: 0 | BM34: 1 | BN34: 0 | BO34: 0 | BP34: 0 | BQ34: 0 | BR34: 0 | BS34: 0 | BT34: 0 | BU34: 0 | BV34: 0 | BW34: 0 | BX34: 0 | BY34: 0 | BZ34: 0 | CA34: 0 | CB34: 0 | CC34: 0 | CD34: 0 | CE34: 0 | CF34: 0 | CG34: 0 | CH34: 0 | CI34: 0 | CJ34: 0 | CK34: 0 | CL34: 0 | CM34: 0 | CN34: 0 | CO34: 0 | CP34: 0 | CQ34: 0 | CR34: 0 | CS34: 0 | CT34: 0 | CU34: 0 | CV34: 0 | CW34: 0 | CX34: 0 | CY34: 0
A35: Bridgeview Elementary | B35: 12 | C35: 277 | D35: 220 | E35: 600 | G35: Bridgeview Elementary | H35: 0 | I35: 0 | J35: 0 | K35: 0 | L35: 0 | M35: 0 | N35: 0 | O35: 0 | P35: 0 | Q35: 0 | R35: 0 | S35: 1 | T35: 0 | U35: 0 | V35: 0 | W35: 0 | X35: 0 | Y35: 0 | Z35: 0 | AA35: 0 | AB35: 0 | AC35: 0 | AD35: 0 | AE35: 0 | AF35: 0 | AG35: 0 | AH35: 0 | AI35: 0 | AJ35: 0 | AK35: 0 | AL35: 0 | AM35: 0 | AN35: 0 | AO35: 0 | AP35: 0 | AQ35: 1 | AR35: 0 | AS35: 0 | AT35: 0 | AU35: 0 | AV35: 0 | AW35: 0 | AX35: 0 | AY35: 0 | AZ35: 0 | BA35: 0 | BB35: 0 | BC35: 0 | BD35: 0 | BE35: 0 | BF35: 0 | BG35: 0 | BH35: 0 | BI35: 0 | BJ35: 0 | BK35: 0 | BL35: 0 | BM35: 0 | BN35: 1 | BO35: 0 | BP35: 0 | BQ35: 0 | BR35: 0 | BS35: 0 | BT35: 0 | BU35: 0 | BV35: 0 | BW35: 0 | BX35: 0 | BY35: 0 | BZ35: 0 | CA35: 0 | CB35: 0 | CC35: 0 | CD35: 0 | CE35: 0 | CF35: 1 | CG35: 0 | CH35: 0 | CI35: 0 | CJ35: 0 | CK35: 0 | CL35: 0 | CM35: 0 | CN35: 0 | CO35: 0 | CP35: 0 | CQ35: 0 | CR35: 0 | CS35: 0 | CT35: 0 | CU35: 0 | CV35: 0 | CW35: 0 | CX35: 0 | CY35: 0
... A119: Woodland Park Elementary | B119: 96 | C119: 826 | D119: 490 | E119: 600 | G119: Woodland Park Elementary | H119: 0 | I119: 0 | J119: 0 | K119: 0 | L119: 0 | M119: 0 | N119: 1 | O119: 0 | P119: 0 | Q119: 0 | R119: 0 | S119: 0 | T119: 0 | U119: 0 | V119: 0 | W119: 0 | X119: 0 | Y119: 0 | Z119: 0 | AA119: 0 | AB119: 0 | AC119: 0 | AD119: 1 | AE119: 0 | AF119: 0 | AG119: 0 | AH119: 0 | AI119: 0 | AJ119: 0 | AK119: 0 | AL119: 0 | AM119: 0 | AN119: 1 | AO119: 0 | AP119: 0 | AQ119: 0 | AR119: 0 | AS119: 0 | AT119: 0 | AU119: 0 | AV119: 0 | AW119: 0 | AX119: 0 | AY119: 0 | AZ119: 0 | BA119: 0 | BB119: 0 | BC119: 0 | BD119: 0 | BE119: 0 | BF119: 0 | BG119: 0 | BH119: 0 | BI119: 0 | BJ119: 0 | BK119: 0 | BL119: 0 | BM119: 0 | BN119: 0 | BO119: 0 | BP119: 0 | BQ119: 0 | BR119: 0 | BS119: 0 | BT119: 0 | BU119: 0 | BV119: 0 | BW119: 0 | BX119: 0 | BY119: 0 | BZ119: 0 | CA119: 0 | CB119: 0 | CC119: 0 | CD119: 0 | CE119: 0 | CF119: 0 | CG119: 0 | CH119: 0 | CI119: 0 | CJ119: 0 | CK119: 0 | CL119: 1 | CM119: 0 | CN119: 0 | CO119: 0 | CP119: 0 | CQ119: 0 | CR119: 0 | CS119: 0 | CT119: 1 | CU119: 0 | CV119: 0 | CW119: 1 | CX119: 0 | CY119: 1
D120: =SUM(D24:D119) -> 49264
B121: tract | C121: proportion | D121: population | E121: tract | F121: proportion | G121: population | H121: tract | I121: proportion | J121: population | K121: tract | L121: proportion | M121: population
A122: A. H. P. Matthew Elementary | B122: 191.03 | C122: 0.5 | D122: 333 | E122: 191.04 | F122: 0.5 | G122: 307 | J122: 0 | M122: 0
A123: A. J. McLellan Elementary | B123: 182.02 | C123: 0.5 | D123: 816 | G123: 0 | J123: 0 | M123: 0
A124: Adams Road Elementary | B124: 183.05 | C124: 0.5 | D124: 980 | G124: 0 | J124: 0 | M124: 0
...

Sheet 2025
A1: Census \ Age | B1: 0-4 | C1: 42864 | D1: 43022 | E1: 15-19 | F1: 15-17 | G1: Elementary | H1: Secondary | M1: 0-4 | N1: 42864 | O1: 43022 | P1: 15-19 | Q1: Elem | R1: Sec
A2: 9330192 | B2: 227 | C2: 282 | D2: 216 | E2: 309 | F2: 185 | G2: 412 | H2: 271 | M2: 225 | N2: 268 | O2: 245 | P2: 300 | Q2: =ROUND(N2+O2*0.6,0) -> 415 | R2: =ROUND(O2*0.4+P2*0.6,0) -> 278
A3: 9330186 | B3: 472 | C3: 378 | D3: 329 | E3: 592 | F3: 355 | G3: 575 | H3: 487 | M3: 528 | N3: 501 | O3: 513 | P3: 573 | Q3: =ROUND(N3+O3*0.6,0) -> 809 | R3: =ROUND(O3*0.4+P3*0.6,0) -> 549
A4: 186.02 | B4: 566 | C4: 268 | D4: 23 | E4: 601 | F4: 361 | G4: 282 | H4: 370 | M4: 411 | N4: 406 | O4: 412 | P4: 453 | Q4: =ROUND(N4+O4*0.6,0) -> 653 | R4: =ROUND(O4*0.4+P4*0.6,0) -> 437
A5: 186.05 | B5: 507 | C5: 558 | D5: 809 | E5: 799 | F5: 479 | G5: 1043 | H5: 803 | M5: 571 | N5: 647 | O5: 677 | P5: 665 | Q5: =ROUND(N5+O5*0.6,0) -> 1053 | R5: =ROUND(O5*0.4+P5*0.6,0) -> 670
A6: 186.06 | B6: 91 | C6: 200 | D6: 465 | E6: 378 | F6: 227 | G6: 479 | H6: 413 | M6: 352 | N6: 340 | O6: 344 | P6: 299 | Q6: =ROUND(N6+O6*0.6,0) -> 546 | R6: =ROUND(O6*0.4+P6*0.6,0) -> 317
A7: 185.09 | B7: 546 | C7: 295 | D7: 383 | E7: 366 | F7: 220 | G7: 525 | H7: 373 | M7: 475 | N7: 373 | O7: 381 | P7: 339 | Q7: =ROUND(N7+O7*0.6,0) -> 602 | R7: =ROUND(O7*0.4+P7*0.6,0) -> 356
A8: 185.11 | B8: 498 | C8: 679 | D8: 622 | E8: 574 | F8: 344 | G8: 1052 | H8: 593 | M8: 693 | N8: 718 | O8: 642 | P8: 554 | Q8: =ROUND(N8+O8*0.6,0) -> 1103 | R8: =ROUND(O8*0.4+P8*0.6,0) -> 589
A9: 185.1 | B9: 52 | C9: 195 | D9: 272 | E9: 549 | F9: 329 | G9: 358 | H9: 438 | M9: 554 | N9: 556 | O9: 482 | P9: 473 | Q9: =ROUND(N9+O9*0.6,0) -> 845 | R9: =ROUND(O9*0.4+P9*0.6,0) -> 477
A10: 185.21 | B10: 441 | C10: 403 | D10: 245 | E10: 248 | F10: 149 | G10: 550 | H10: 247 | M10: 270 | N10: 287 | O10: 299 | P10: 264 | Q10: =ROUND(N10+O10*0.6,0) -> 466 | R10: =ROUND(O10*0.4+P10*0.6,0) -> 278
A11: 185.22 | B11: 383 | C11: 310 | D11: 288 | E11: 324 | F11: 194 | G11: 483 | H11: 309 | M11: 375 | N11: 320 | O11: 290 | P11: 310 | Q11: =ROUND(N11+O11*0.6,0) -> 494 | R11: =ROUND(O11*0.4+P11*0.6,0) -> 302
A12: 185.17 | B12: 199 | C12: 138 | D12: 172 | E12: 258 | F12: 155 | G12: 241 | H12: 224 | M12: 218 | N12: 202 | O12: 232 | P12: 291 | Q12: =ROUND(N12+O12*0.6,0) -> 341 | R12: =ROUND(O12*0.4+P12*0.6,0) -> 267
A13: 185.18 | B13: 237 | C13: 313 | D13: 357 | E13: 383 | F13: 230 | G13: 527 | H13: 373 | M13: 334 | N13: 339 | O13: 359 | P13: 403 | Q13: =ROUND(N13+O13*0.6,0) -> 554 | R13: =ROUND(O13*0.4+P13*0.6,0) -> 385
... A33: 187.04 | B33: 110 | C33: 113 | D33: 120 | E33: 108 | F33: 65 | G33: 185 | H33: 113 | M33: 109 | N33: 113 | O33: 121 | P33: 108 | Q33: =ROUND(N33+O33*0.6,0) -> 186 | R33: =ROUND(O33*0.4+P33*0.6,0) -> 113
A34: 187.05 | B34: 633 | C34: 526 | D34: 394 | E34: 672 | F34: 403 | G34: 762 | H34: 561 | I34: =H34*0.75 -> 420.75 | M34: 698 | N34: 612 | O34: 582 | P34: 573 | Q34: =ROUND(N34+O34*0.6,0) -> 961 | R34: =ROUND(O34*0.4+P34*0.6,0) -> 577
A35: 184.02 | B35: 676 | C35: 691 | D35: 395 | E35: 515 | F35: 309 | G35: 928 | H35: 467 | M35: 565 | N35: 570 | O35: 499 | P35: 535 | Q35: =ROUND(N35+O35*0.6,0) -> 869 | R35: =ROUND(O35*0.4+P35*0.6,0) -> 521
A36: 184.15 | B36: 142 | C36: 122 | D36: 191 | E36: 334 | F36: 200 | G36: 237 | H36: 276 | M36: 186 | N36: 192 | O36: 259 | P36: 336 | Q36: =ROUND(N36+O36*0.6,0) -> 347 | R36: =ROUND(O36*0.4+P36*0.6,0) -> 305
A37: 184.16 | B37: 419 | C37: 457 | D37: 322 | E37: 205 | F37: 123 | G37: 650 | H37: 252 | M37: 360 | N37: 399 | O37: 447 | P37: 463 | Q37: =ROUND(N37+O37*0.6,0) -> 667 | R37: =ROUND(O37*0.4+P37*0.6,0) -> 457
A38: 184.07 | B38: 354 | C38: 246 | D38: 26 | E38: 210 | F38: 126 | G38: 262 | H38: 136 | M38: 341 | N38: 339 | O38: 372 | P38: 350 | Q38: =ROUND(N38+O38*0.6,0) -> 562 | R38: =ROUND(O38*0.4+P38*0.6,0) -> 359
A39: 184.08 | B39: 510 | C39: 450 | D39: 521 | E39: 560 | F39: 336 | G39: 763 | H39: 544 | M39: 480 | N39: 516 | O39: 593 | P39: 555 | Q39: =ROUND(N39+O39*0.6,0) -> 872 | R39: =ROUND(O39*0.4+P39*0.6,0) -> 570
A40: 184.06 | B40: 1395 | C40: 1446 | D40: 1096 | E40: 1109 | F40: 665 | G40: 2104 | H40: 1103 | M40: 1479 | N40: 1408 | O40: 1235 | P40: 1086 | Q40: =ROUND(N40+O40*0.6,0) -> 2149 | R40: =ROUND(O40*0.4+P40*0.6,0) -> 1146
A41: 184.12 | B41: 865 | C41: 1032 | D41: 747 | E41: 786 | F41: 472 | G41: 1480 | H41: 771 | M41: 936 | N41: 633 | O41: 669 | P41: 676 | Q41: =ROUND(N41+O41*0.6,0) -> 1034 | R41: =ROUND(O41*0.4+P41*0.6,0) -> 673
A42: 184.13 | B42: 473 | C42: 193 | D42: 225 | E42: 429 | F42: 257 | G42: 328 | H42: 347 | M42: 473 | N42: 419 | O42: 400 | P42: 429 | Q42: =ROUND(N42+O42*0.6,0) -> 659 | R42: =ROUND(O42*0.4+P42*0.6,0) -> 417
A43: 184.14 | B43: 1529 | C43: 1203 | D43: 768 | E43: 621 | F43: 373 | G43: 1664 | H43: 680 | M43: 1352 | N43: 1137 | O43: 764 | P43: 685 | Q43: =ROUND(N43+O43*0.6,0) -> 1595 | R43: =ROUND(O43*0.4+P43*0.6,0) -> 717
A44: 182.03 | B44: 365 | C44: 103 | D44: 29 | E44: 252 | F44: 151 | G44: 120 | H44: 163 | M44: 206 | N44: 195 | O44: 277 | P44: 410 | Q44: =ROUND(N44+O44*0.6,0) -> 361 | R44: =ROUND(O44*0.4+P44*0.6,0) -> 357
A45: 184.11 | B45: 869 | C45: 530 | D45: 948 | E45: 1113 | F45: 668 | G45: 1099 | H45: 1047 | M45: 1002 | N45: 961 | O45: 1061 | P45: 986 | Q45: =ROUND(N45+O45*0.6,0) -> 1598 | R45: =ROUND(O45*0.4+P45*0.6,0) -> 1016
A46: 184.1 | B46: 50 | C46: 464 | D46: 407 | E46: 743 | F46: 446 | G46: 708 | H46: 609 | M46: 389 | N46: 464 | O46: 523 | P46: 609 | Q46: =ROUND(N46+O46*0.6,0) -> 778 | R46: =ROUND(O46*0.4+P46*0.6,0) -> 575
... A102: 185.05 | B102: 426 | C102: 127 | D102: 424 | E102: 764 | F102: 458 | G102: 381 | H102: 628 | M102: 448 | N102: 464 | O102: 568 | P102: 600 | Q102: =ROUND(N102+O102*0.6,0) -> 805 | R102: =ROUND(O102*0.4+P102*0.6,0) -> 587
G103: =SUM(G2:G102) -> 59893 | H103: =SUM(H2:H102) -> 41180 | Q103: =SUM(Q2:Q102) -> 66081 | R103: =SUM(R2:R102) -> 43855
A104: 9330192 | B104: 1 | C104: 1 | D104: 1 | E104: 1 | M104: 0.058341715 | N104: 0.060977123 | O104: 0.067469408 | P104: 0.070623273 | Q104: =N104+0.6*O104 -> 0.10145877 | R104: =0.6*P104+0.4*O104 -> 0.069361727
A105: 9330186 | B105: 1 | C105: 1 | D105: 2 | E105: 1 | Q105: =Q103/Q104 -> 651308.92 | R105: =R103/R104 -> 632265.11
A106: 186.02 | B106: 1 | C106: 2 | D106: 18 | E106: 1
A107: 186.05 | B107: 1 | C107: 1 | D107: 1 | E107: 1
A108: 186.06 | B108: 4 | C108: 2 | D108: 1 | E108: 1
A109: 185.09 | B109: 1 | C109: 1 | D109: 1 | E109: 1
A110: 185.11 | B110: 1 | C110: 1 | D110: 1 | E110: 1
A111: 185.1 | B111: 11 | C111: 3 | D111: 2 | E111: 1
A112: 185.21 | B112: 1 | C112: 1 | D112: 1 | E112: 1
A113: 185.22 | B113: 1 | C113: 1 | D113: 1 | E113: 1
A114: 185.17 | B114: 1 | C114: 1 | D114: 1 | E114: 1
...

Sheet 2021
A1: Census \ Age | B1: 0-4 | C1: 42864 | D1: 43022 | E1: 15-19 | F1: 15-17 | G1: Elementary | H1: Secondary
A2: 9330192 | B2: 224 | C2: 276 | D2: 221 | E2: 304 | F2: 182 | G2: 409 | H2: 270
A3: 9330186 | B3: 462 | C3: 388 | D3: 356 | E3: 560 | F3: 336 | G3: 602 | H3: 478
A4: 186.02 | B4: 512 | C4: 283 | D4: 63 | E4: 546 | F4: 328 | G4: 321 | H4: 353
A5: 186.05 | B5: 492 | C5: 546 | D5: 734 | E5: 724 | F5: 434 | G5: 986 | H5: 728
A6: 186.06 | B6: 152 | C6: 227 | D6: 416 | E6: 344 | F6: 206 | G6: 477 | H6: 372
A7: 185.09 | B7: 497 | C7: 295 | D7: 359 | E7: 338 | F7: 203 | G7: 510 | H7: 347
A8: 185.11 | B8: 532 | C8: 663 | D8: 604 | E8: 546 | F8: 328 | G8: 1025 | H8: 570
A9: 185.1 | B9: 180 | C9: 280 | D9: 315 | E9: 511 | F9: 307 | G9: 469 | H9: 433
A10: 185.21 | B10: 395 | C10: 370 | D10: 252 | E10: 246 | F10: 148 | G10: 521 | H10: 249
A11: 185.22 | B11: 366 | C11: 310 | D11: 282 | E11: 304 | F11: 182 | G11: 479 | H11: 295
A12: 185.17 | B12: 187 | C12: 141 | D12: 171 | E12: 244 | F12: 146 | G12: 244 | H12: 214
A13: 185.18 | B13: 249 | C13: 311 | D13: 350 | E13: 378 | F13: 227 | G13: 521 | H13: 367
... A101: 181.15 | B101: 74 | C101: 119 | D101: 103 | E101: 162 | F101: 97 | G101: 181 | H101: 138

Sheet 2016
A1: Census \ Age | B1: 0-4 | C1: 42864 | D1: 43022 | E1: 15-19 | F1: Total | G1: 15-17
A2: 9330192 | B2: 221 | C2: 257 | D2: 256 | E2: 291 | F2: 4194 | G2: 175 | J2: 0.052766247 | K2: 0.061393041 | L2: 0.061009367 | M2: 0.069489853 | N2: 411 | O2: 277
A3: 9330186 | B3: 475 | C3: 460 | D3: 479 | E3: 505 | F3: 7494 | G3: 303 | J3: 0.063427302 | K3: 0.061325578 | L3: 0.063977185 | M3: 0.067346993 | N3: 747 | O3: 495
A4: 186.02 | B4: 370 | C4: 379 | D4: 399 | E4: 409 | F4: 6106 | G4: 245 | J4: 0.060571392 | K4: 0.06203031 | L4: 0.065340411 | M4: 0.067050533 | N4: 618 | O4: 405
A5: 186.05 | B5: 503 | C5: 573 | D5: 567 | E5: 556 | F5: 7592 | G5: 334 | J5: 0.06624341 | K5: 0.075534112 | L5: 0.07468327 | M5: 0.073200416 | N5: 913 | O5: 560
A6: 186.06 | B6: 333 | C6: 315 | D6: 301 | E6: 264 | F6: 4206 | G6: 158 | J6: 0.07923151 | K6: 0.07481826 | L6: 0.071589807 | M6: 0.062886289 | N6: 496 | O6: 279
A7: 185.09 | B7: 387 | C7: 333 | D7: 322 | E7: 282 | F7: 5127 | G7: 169 | J7: 0.075415148 | K7: 0.065021811 | L7: 0.06280516 | M7: 0.054988243 | N7: 526 | O7: 298
A8: 185.11 | B8: 646 | C8: 644 | D8: 574 | E8: 489 | F8: 7844 | G8: 293 | J8: 0.082347043 | K8: 0.082155766 | L8: 0.073228873 | M8: 0.062296973 | N8: 988 | O8: 523
A9: 185.1 | B9: 502 | C9: 499 | D9: 430 | E9: 404 | F9: 5894 | G9: 242 | J9: 0.085120227 | K9: 0.084672241 | L9: 0.072879553 | M9: 0.068469602 | N9: 757 | O9: 414
A10: 185.21 | B10: 280 | C10: 289 | D10: 279 | E10: 250 | F10: 3845 | G10: 150 | J10: 0.072864504 | K10: 0.075216187 | L10: 0.072452995 | M10: 0.065008172 | N10: 456 | O10: 262
A11: 185.22 | B11: 323 | C11: 293 | D11: 258 | E11: 261 | F11: 3771 | G11: 157 | J11: 0.085633783 | K11: 0.077657682 | L11: 0.068362265 | M11: 0.069284698 | N11: 448 | O11: 260
A12: 185.17 | B12: 175 | C12: 175 | D12: 197 | E12: 235 | F12: 3520 | G12: 141 | J12: 0.049609843 | K12: 0.049693019 | L12: 0.056042591 | M12: 0.066892743 | N12: 293 | O12: 220
A13: 185.18 | B13: 308 | C13: 325 | D13: 348 | E13: 388 | F13: 5295 | G13: 233 | J13: 0.058231362 | K13: 0.061315181 | L13: 0.065809093 | M13: 0.073211071 | N13: 534 | O13: 372
... A101: 181.15 | B101: 100 | C101: 110 | D101: 235 | E101: 155 | F101: 2600 | G101: 93 | J101: 0.035397126 | K101: 0.040863741 | L101: 0.050003188 | M101: 0.057226928 | N101: 251 | O101: 187
A102: 185.05 | B102: 402 | C102: 449 | D102: 522 | E102: 518 | F102: 5943 | G102: 311 | J102: =(0.06826568266+'2011'!H102)/2 -> 0.067611102 | K102: =(0.0857933579335793+'2011'!I102)/2 -> 0.075505375 | L102: =(0.0922509225092251+'2011'!J102)/2 -> 0.087864592 | M102: =(0.0821033210332103+'2011'!K102)/2 -> 0.087138617 | N102: 762 | O102: 520
J103: =SUM(J2:J102)/101 -> 0.058341715 | K103: =SUM(K2:K102)/101 -> 0.060977123 | L103: =SUM(L2:L102)/101 -> 0.067469408 | M103: =SUM(M2:M102)/101 -> 0.070623273 | N103: =K103+0.6*L103 -> 0.10145877 | O103: =0.6*M103+0.4*L103 -> 0.069361727
M104: Total | N104: =SUM(N2:N102) -> 55797 | O104: =SUM(O2:O102) -> 36949
M105: Enroll | N105: 40016 | O105: 27300

Sheet 2011
A1: Census \ Age | B1: 0-4 | C1: 42864 | D1: 43022 | E1: 15-19 | F1: Total | H1: 0-4 % | I1: 5-9 % | J1: 10-14 % | K1: 15-19%
A2: 9330192 | B2: 220 | C2: 265 | D2: 230 | E2: 295 | F2: 4145 | H2: =B2/$F2 -> 0.053075995 | I2: =C2/$F2 -> 0.063932449 | J2: =D2/$F2 -> 0.05548854 | K2: =E2/$F2 -> 0.071170084
A3: 9330186 | B3: 440 | C3: 410 | D3: 415 | E3: 485 | F3: 7137 | H3: =B3/F3 -> 0.061650553 | I3: =C3/$F3 -> 0.057447107 | J3: =D3/$F3 -> 0.058147681 | K3: =E3/$F3 -> 0.067955724
A4: 186.02 | B4: 345 | C4: 330 | D4: 325 | E4: 380 | F4: 5495 | H4: =B4/F4 -> 0.062784349 | I4: =C4/$F4 -> 0.060054595 | J4: =D4/$F4 -> 0.059144677 | K4: =E4/$F4 -> 0.069153776
A5: 186.05 | B5: 460 | C5: 520 | D5: 570 | E5: 560 | F5: 7187 | H5: =B5/F5 -> 0.064004452 | I5: =C5/$F5 -> 0.072352859 | J5: =D5/$F5 -> 0.079309865 | K5: =E5/$F5 -> 0.077918464
A6: 186.06 | B6: 295 | C6: 290 | D6: 305 | E6: 265 | F6: 4079 | H6: =B6/F6 -> 0.072321647 | I6: =C6/$F6 -> 0.071095857 | J6: =D6/$F6 -> 0.074773229 | K6: =E6/$F6 -> 0.064966904
A7: 185.09 | B7: 405 | C7: 295 | D7: 315 | E7: 285 | F7: 5002 | H7: =B7/F7 -> 0.080967613 | I7: =C7/$F7 -> 0.058976409 | J7: =D7/$F7 -> 0.06297481 | K7: =E7/$F7 -> 0.056977209
A8: 185.11 | B8: 595 | C8: 635 | D8: 570 | E8: 495 | F8: 7856 | H8: =B8/F8 -> 0.075738289 | I8: =C8/$F8 -> 0.080829939 | J8: =D8/$F8 -> 0.072556008 | K8: =E8/$F8 -> 0.063009165
A9: 185.1 | B9: 465 | C9: 470 | D9: 410 | E9: 415 | F9: 5781 | H9: =B9/F9 -> 0.080435911 | I9: =C9/$F9 -> 0.081300813 | J9: =D9/$F9 -> 0.070921986 | K9: =E9/$F9 -> 0.071786888
A10: 185.21 | B10: 230 | C10: 250 | D10: 275 | E10: 240 | F10: 3640 | H10: =B10/F10 -> 0.063186813 | I10: =C10/$F10 -> 0.068681319 | J10: =D10/$F10 -> 0.075549451 | K10: =E10/$F10 -> 0.065934066
A11: 185.22 | B11: 375 | C11: 310 | D11: 285 | E11: 315 | F11: 4214 | H11: =B11/F11 -> 0.088989084 | I11: =C11/$F11 -> 0.073564309 | J11: =D11/$F11 -> 0.067631704 | K11: =E11/$F11 -> 0.074750831
A12: 185.17 | B12: 170 | C12: 145 | D12: 170 | E12: 225 | F12: 3649 | H12: =B12/F12 -> 0.046588106 | I12: =C12/$F12 -> 0.039736914 | J12: =D12/$F12 -> 0.046588106 | K12: =E12/$F12 -> 0.061660729
A13: 185.18 | B13: 305 | C13: 300 | D13: 315 | E13: 355 | F13: 4779 | H13: =B13/F13 -> 0.063820883 | I13: =C13/$F13 -> 0.062774639 | J13: =D13/$F13 -> 0.065913371 | K13: =E13/$F13 -> 0.074283323
A14: 185.19 | B14: 410 | C14: 355 | D14: 365 | E14: 375 | F14: 5418 | H14: =B14/F14 -> 0.07567368 | I14: =C14/$F14 -> 0.065522333 | J14: =D14/$F14 -> 0.067368032 | K14: =E14/$F14 -> 0.069213732
... A75: 183.06 | B75: 150 | C75: 130 | D75: 140 | E75: 135 | F75: 2356 | H75: =B75/F75 -> 0.063667233 | I75: =C75/$F75 -> 0.055178268 | J75: =D75/$F75 -> 0.05942275 | K75: =E75/$F75 -> 0.057300509
A76: 183.08 | B76: 750 | C76: 445 | D76: 360 | E76: 323 | F76: 7017 | H76: =B76/F76 -> 0.10688328 | I76: =C76/$F76 -> 0.063417415 | J76: =D76/$F76 -> 0.051303976 | K76: =E76/$F76 -> 0.046031067 | L76: =SUM(B76:D76) -> 1555
A77: 183.09 | B77: 750 | C77: 445 | D77: 360 | E77: 322 | F77: 7017 | H77: =B77/F77 -> 0.10688328 | I77: =C77/$F77 -> 0.063417415 | J77: =D77/$F77 -> 0.051303976 | K77: =E77/$F77 -> 0.045888556
A78: 182.06 | B78: 45 | C78: 70 | D78: 90 | E78: 100 | F78: 1180 | H78: =B78/F78 -> 0.038135593 | I78: =C78/$F78 -> 0.059322034 | J78: =D78/$F78 -> 0.076271186 | K78: =E78/$F78 -> 0.084745763
A79: 188.06 | B79: 65 | C79: 70 | D79: 95 | E79: 90 | F79: 1184 | H79: =B79/F79 -> 0.054898649 | I79: =C79/$F79 -> 0.059121622 | J79: =D79/$F79 -> 0.080236486 | K79: =E79/$F79 -> 0.076013514
A80: 188.05 | B80: 115 | C80: 160 | D80: 205 | E80: 275 | F80: 2687 | H80: =B80/F80 -> 0.04279866 | I80: =C80/$F80 -> 0.059545962 | J80: =D80/$F80 -> 0.076293264 | K80: =E80/$F80 -> 0.10234462
A81: 182.01 | B81: 210 | C81: 245 | D81: 275 | E81: 295 | F81: 4160 | H81: =B81/F81 -> 0.050480769 | I81: =C81/$F81 -> 0.058894231 | J81: =D81/$F81 -> 0.066105769 | K81: =E81/$F81 -> 0.070913462
A82: 180.01 | B82: 490 | C82: 535 | D82: 455 | E82: 435 | F82: 6910 | H82: =B82/F82 -> 0.070911722 | I82: =C82/$F82 -> 0.077424023 | J82: =D82/$F82 -> 0.065846599 | K82: =E82/$F82 -> 0.062952243
A83: 180.04 | B83: 325 | C83: 280 | D83: 343 | E83: 368 | F83: 6004 | H83: =B83/F83 -> 0.05413058 | I83: =C83/$F83 -> 0.046635576 | J83: =D83/$F83 -> 0.057128581 | K83: =E83/$F83 -> 0.061292472
A84: 180.03 | B84: 325 | C84: 280 | D84: 342 | E84: 367 | F84: 6003 | H84: =B84/F84 -> 0.054139597 | I84: =C84/$F84 -> 0.046643345 | J84: =D84/$F84 -> 0.056971514 | K84: =E84/$F84 -> 0.061136099
A85: 181.13 | B85: 110 | C85: 125 | D85: 175 | E85: 210 | F85: 3274 | H85: =B85/F85 -> 0.033598045 | I85: =C85/$F85 -> 0.038179597 | J85: =D85/$F85 -> 0.053451436 | K85: =E85/$F85 -> 0.064141723
A86: 181.12 | B86: 100 | C86: 155 | D86: 215 | E86: 225 | F86: 2884 | H86: =B86/F86 -> 0.034674064 | I86: =C86/$F86 -> 0.053744799 | J86: =D86/$F86 -> 0.074549237 | K86: =E86/$F86 -> 0.078016644
A87: 181.14 | B87: 205 | C87: 170 | D87: 190 | E87: 215 | F87: 3706 | H87: =B87/F87 -> 0.055315704 | I87: =C87/$F87 -> 0.04587156 | J87: =D87/$F87 -> 0.051268214 | K87: =E87/$F87 -> 0.058014031
A88: 181.1 | B88: 145 | C88: 220 | D88: 280 | E88: 410 | F88: 5189 | H88: =B88/F88 -> 0.027943727 | I88: =C88/$F88 -> 0.042397379 | J88: =D88/$F88 -> 0.053960301 | K88: =E88/$F88 -> 0.079013297
... A101: 181.15 | B101: 82 | C101: 110 | D101: 115 | E101: 152 | F101: 2561 | H101: =B101/F101 -> 0.032018743 | I101: =C101/$F101 -> 0.042951972 | J101: =D101/$F101 -> 0.044904334 | K101: =E101/$F101 -> 0.059351816
A102: 185.05 | B102: 385 | C102: 375 | D102: 480 | E102: 530 | F102: 5750 | H102: =B102/$F$102 -> 0.066956522 | I102: =C102/$F$102 -> 0.065217391 | J102: =D102/$F$102 -> 0.083478261 | K102: =E102/$F$102 -> 0.092173913
H103: =SUM(H2:H102)/101 -> 0.057738114 | I103: =SUM(I2:I102)/101 -> 0.058259341 | J103: =SUM(J2:J102)/101 -> 0.064161221 | K103: =SUM(K2:K102)/101 -> 0.070564582 | L103: =I103+0.6*J103 -> 0.096756074 | M103: =0.6*K103+0.4*J103 -> 0.068003238

Sheet 2006
A1: Census \ Age | B1: 0-4 | C1: 42864 | D1: 43022 | E1: 15-19 | F1: total | H1: 0-4 % | I1: 5-9 % | J1: 10-14 % | K1: 15-19%
A2: 9330192 | B2: 205 | C2: 230 | D2: 260 | E2: 265 | F2: 3908 | H2: =B2/$F2 -> 0.052456499 | I2: =C2/$F2 -> 0.058853634 | J2: =D2/$F2 -> 0.066530194 | K2: =E2/$F2 -> 0.067809621
A3: 9330186 | B3: 425 | C3: 425 | D3: 455 | E3: 435 | F3: 6518 | H3: =B3/F3 -> 0.06520405 | I3: =C3/$F3 -> 0.06520405 | J3: =D3/$F3 -> 0.069806689 | K3: =E3/$F3 -> 0.066738263
A4: 186.02 | B4: 310 | C4: 340 | D4: 380 | E4: 345 | F4: 5312 | H4: =B4/F4 -> 0.058358434 | I4: =C4/$F4 -> 0.064006024 | J4: =D4/$F4 -> 0.071536145 | K4: =E4/$F4 -> 0.064947289
A5: 186.05 | B5: 435 | C5: 500 | D5: 445 | E5: 435 | F5: 6352 | H5: =B5/F5 -> 0.068482368 | I5: =C5/$F5 -> 0.078715365 | J5: =D5/$F5 -> 0.070056675 | K5: =E5/$F5 -> 0.068482368
A6: 186.06 | B6: 340 | C6: 310 | D6: 270 | E6: 240 | F6: 3947 | H6: =B6/F6 -> 0.086141373 | I6: =C6/$F6 -> 0.078540664 | J6: =D6/$F6 -> 0.068406385 | K6: =E6/$F6 -> 0.060805675
A7: 185.09 | B7: 290 | C7: 295 | D7: 260 | E7: 220 | F7: 4151 | H7: =B7/F7 -> 0.069862684 | I7: =C7/$F7 -> 0.071067213 | J7: =D7/$F7 -> 0.06263551 | K7: =E7/$F7 -> 0.052999277
A8: 185.11 | B8: 650 | C8: 610 | D8: 540 | E8: 450 | F8: 7307 | H8: =B8/F8 -> 0.088955796 | I8: =C8/$F8 -> 0.083481593 | J8: =D8/$F8 -> 0.073901738 | K8: =E8/$F8 -> 0.061584782
A9: 185.1 | B9: 510 | C9: 500 | D9: 425 | E9: 370 | F9: 5679 | H9: =B9/F9 -> 0.089804543 | I9: =C9/$F9 -> 0.08804367 | J9: =D9/$F9 -> 0.074837119 | K9: =E9/$F9 -> 0.065152316
A10: 185.21 | B10: 313 | C10: 310 | D10: 263 | E10: 243 | F10: 3792 | H10: =B10/F10 -> 0.082542194 | I10: =C10/$F10 -> 0.081751055 | J10: =D10/$F10 -> 0.06935654 | K10: =E10/$F10 -> 0.064082278
A11: 185.22 | B11: 312 | C11: 310 | D11: 262 | E11: 242 | F11: 3792 | H11: =B11/F11 -> 0.082278481 | I11: =C11/$F11 -> 0.081751055 | J11: =D11/$F11 -> 0.069092827 | K11: =E11/$F11 -> 0.063818565
A12: 185.17 | B12: 135 | C12: 153 | D12: 168 | E12: 185 | F12: 2565 | H12: =B12/F12 -> 0.052631579 | I12: =C12/$F12 -> 0.059649123 | J12: =D12/$F12 -> 0.065497076 | K12: =E12/$F12 -> 0.072124756
A13: 185.18 | B13: 270 | C13: 307 | D13: 337 | E13: 370 | F13: 5129 | H13: =B13/F13 -> 0.052641841 | I13: =C13/$F13 -> 0.059855722 | J13: =D13/$F13 -> 0.065704816 | K13: =E13/$F13 -> 0.072138818
A14: 185.19 | B14: 380 | C14: 315 | D14: 317.5 | E14: 272.5 | F14: 4235 | H14: =B14/F14 -> 0.089728453 | I14: =C14/$F14 -> 0.074380165 | J14: =D14/$F14 -> 0.074970484 | K14: =E14/$F14 -> 0.064344746
... A101: 181.15 | B101: 95 | C101: 95 | D101: 135 | E101: 135 | F101: 2450 | H101: =B101/F101 -> 0.03877551 | I101: =C101/$F101 -> 0.03877551 | J101: =D101/$F101 -> 0.055102041 | K101: =E101/$F101 -> 0.055102041
A102: 185.05 | B102: 370 | C102: 465 | D102: 500 | E102: 445 | F102: 5420 | H102: 0.068265683 | I102: =C102/$F102 -> 0.085793358 | J102: =D102/$F102 -> 0.092250923 | K102: =E102/$F102 -> 0.082103321
H103: =SUM(H2:H102)/101 -> 0.058945316 | I103: =SUM(I2:I102)/101 -> 0.063694904 | J103: =SUM(J2:J102)/101 -> 0.070777595 | K103: =SUM(K2:K102)/101 -> 0.070681964 | L103: =I103+0.6*J103 -> 0.10616146 | M103: =0.6*K103+0.4*J103 -> 0.070720216

Sheet 2001
A1: Census \ Age | B1: 0-4 | C1: 42864 | D1: 43022 | E1: 15 | F1: total
A2: 9330192 | B2: 216 | C2: 251 | D2: 250 | E2: 285 | F2: 4096 | H2: 0.052766247 | I2: 0.061393041 | J2: 0.061009367 | K2: 0.069489853
A3: 9330186 | B3: 382 | C3: 369 | D3: 385 | E3: 405 | F3: 6015 | H3: 0.063427302 | I3: 0.061325578 | J3: 0.063977185 | K3: 0.067346993
A4: 186.02 | B4: 301 | C4: 309 | D4: 325 | E4: 334 | F4: 4977 | H4: 0.060571392 | I4: 0.06203031 | J4: 0.065340411 | K4: 0.067050533
A5: 186.05 | B5: 385 | C5: 439 | D5: 434 | E5: 425 | F5: 5806 | H5: 0.06624341 | I5: 0.075534112 | J5: 0.07468327 | K5: 0.073200416
A6: 186.06 | B6: 277 | C6: 262 | D6: 250 | E6: 220 | F6: 3496 | H6: 0.07923151 | I6: 0.07481826 | J6: 0.071589807 | K6: 0.062886289
A7: 185.09 | B7: 293 | C7: 253 | D7: 244 | E7: 214 | F7: 3890 | H7: 0.075415148 | I7: 0.065021811 | J7: 0.06280516 | K7: 0.054988243
A8: 185.11 | B8: 542 | C8: 541 | D8: 482 | E8: 410 | F8: 6585 | H8: 0.082347043 | I8: 0.082155766 | J8: 0.073228873 | K8: 0.062296973
A9: 185.1 | B9: 402 | C9: 399 | D9: 344 | E9: 323 | F9: 4717 | H9: 0.085120227 | I9: 0.084672241 | J9: 0.072879553 | K9: 0.068469602
A10: 185.21 | B10: 251 | C10: 259 | D10: 250 | E10: 224 | F10: =6891/2 -> 3445.5 | H10: 0.072864504 | I10: 0.075216187 | J10: 0.072452995 | K10: 0.065008172
A11: 185.22 | B11: 295 | C11: 268 | D11: 236 | E11: 239 | F11: =6891/2 -> 3445.5 | H11: 0.085633783 | I11: 0.077657682 | J11: 0.068362265 | K11: 0.069284698
A12: 185.17 | B12: 117 | C12: 117 | D12: 132 | E12: 157 | F12: 2351 | H12: 0.049609843 | I12: 0.049693019 | J12: 0.056042591 | K12: 0.066892743
A13: 185.18 | B13: 274 | C13: 288 | D13: 309 | E13: 344 | F13: 4701 | H13: 0.058231362 | I13: 0.061315181 | J13: 0.065809093 | K13: 0.073211071
A14: 185.19 | B14: 250 | C14: 212 | D14: 215 | E14: 202 | F14: =6051/2 -> 3025.5 | H14: 0.082701067 | I14: 0.069951249 | J14: 0.071169258 | K14: 0.066779239
A15: 185.2 | B15: 258 | C15: 235 | D15: 227 | E15: 214 | F15: =6051/2 -> 3025.5 | H15: 0.085421631 | I15: 0.077747487 | J15: 0.074922846 | K15: 0.070649911
A16: 185.08 | B16: 50 | C16: 61 | D16: 75 | E16: 103 | F16: 1209 | H16: 0.041688786 | I16: 0.050696955 | J16: 0.061730053 | K16: 0.085262941
A17: 185.07 | B17: 375 | C17: 409 | D17: 428 | E17: 434 | F17: 5548 | H17: 0.067669867 | I17: 0.073640259 | J17: 0.07710561 | K17: 0.078154026
A18: 185.12 | B18: 411 | C18: 453 | D18: 480 | E18: 434 | F18: 6133 | H18: 0.06703485 | I18: 0.073860576 | J18: 0.078345136 | K18: 0.07072437
A19: 185.16 | B19: 343 | C19: 350 | D19: 350 | E19: 321 | F19: 4425 | H19: 0.077553348 | I19: 0.079091059 | J19: 0.07906712 | K19: 0.072469537
A20: 185.15 | B20: 419 | C20: 365 | D20: 319 | E20: 286 | F20: 5086 | H20: 0.082473048 | I20: 0.07168113 | J20: 0.062747503 | K20: 0.056243026
A21: 186.07 | B21: 342 | C21: 346 | D21: 336 | E21: 306 | F21: 4547 | H21: 0.075124028 | I21: 0.076050912 | J21: 0.073918462 | K21: 0.067383829
A22: 186.08 | B22: 369 | C22: 398 | D22: 405 | E22: 392 | F22: 5259 | H22: 0.070150311 | I22: 0.075656088 | J22: 0.077001666 | K22: 0.074511225
A23: 191.03 | B23: 312 | C23: 302 | D23: 295 | E23: 326 | F23: 4484 | H23: 0.069536325 | I23: 0.067256453 | J23: 0.065771934 | K23: 0.072639897
A24: 191.04 | B24: 248 | C24: 220 | D24: 229 | E24: 234 | F24: 4603 | H24: 0.053895746 | I24: 0.047886979 | J24: 0.049707832 | K24: 0.050861147
A25: 191.05 | B25: 206 | C25: 203 | D25: 241 | E25: 256 | F25: 3739 | H25: 0.055164271 | I25: 0.054158926 | J25: 0.064483754 | K25: 0.068393058
